ID: 29008
Title: br: BACKUP statement panics with "runtime error:slice bounds out of range" when SEM is enabled
Description:
## Bug Report

### 1. Minimal reproduce step (Required)

<!-- a step by step guide for reproducing the bug. -->

```
create table `t` (id int primary key);
backup table t to 'noop://';
```


### 2. What did you expect to see? (Required)

Successful backup

### 3. What did you see instead (Required)

```
ERROR: 1105 (HY000): runtime error: slice bounds out of range [:8] with length 7
```

From logs:
```
[2021/10/21 08:31:56.531 +02:00] [ERROR] [conn.go:919] ["connection running loop panic"] [conn=13] [lastSQL="backup table t to 'noop://'"] [err="runtime error: slice bounds out of range [:8] with length 7"] ...
```

### 4. What is your TiDB version? (Required)

<!-- Paste the output of SELECT tidb_version() -->

```
tidb_version(): Release Version: v5.2.1
Edition: Community
Git Commit Hash: cd8fb24c5f7ebd9d479ed228bb41848bd5e97445
Git Branch: heads/refs/tags/v5.2.1
UTC Build Time: 2021-09-08 02:32:56
GoVersion: go1.16.4
Race Enabled: false
TiKV Min Version: v3.0.0-60965b006877ca7234adaced7890d7b029ed1306
Check Table Before Drop: false
1 row in set (0.0005 sec)
```